ERROR 2025-03-10 23:25:44,099 log Internal Server Error: /auth/signup/
Traceback (most recent call last):
  File "/home/alain/anaconda3/lib/python3.12/site-packages/rest_framework/serializers.py", line 989, in create
    instance = ModelClass._default_manager.create(**validated_data)
               ^^^^^^^^^^^^^^^^^^^^^^^^^^^^^^^^^^^^^^^^^^^^^^^^^^^^
  File "/home/alain/anaconda3/lib/python3.12/site-packages/django/db/models/manager.py", line 87, in manager_method
    return getattr(self.get_queryset(), name)(*args, **kwargs)
           ^^^^^^^^^^^^^^^^^^^^^^^^^^^^^^^^^^^^^^^^^^^^^^^^^^^
  File "/home/alain/anaconda3/lib/python3.12/site-packages/django/db/models/query.py", line 677, in create
    obj = self.model(**kwargs)
          ^^^^^^^^^^^^^^^^^^^^
  File "/home/alain/anaconda3/lib/python3.12/site-packages/django/db/models/base.py", line 567, in __init__
    raise TypeError(
TypeError: VectorUser() got unexpected keyword arguments: 'password2'

During handling of the above exception, another exception occurred:

Traceback (most recent call last):
  File "/home/alain/anaconda3/lib/python3.12/site-packages/django/core/handlers/exception.py", line 55, in inner
    response = get_response(request)
               ^^^^^^^^^^^^^^^^^^^^^
  File "/home/alain/anaconda3/lib/python3.12/site-packages/django/core/handlers/base.py", line 197, in _get_response
    response = wrapped_callback(request, *callback_args, **callback_kwargs)
               ^^^^^^^^^^^^^^^^^^^^^^^^^^^^^^^^^^^^^^^^^^^^^^^^^^^^^^^^^^^^
  File "/home/alain/anaconda3/lib/python3.12/site-packages/django/views/decorators/csrf.py", line 65, in _view_wrapper
    return view_func(request, *args, **kwargs)
           ^^^^^^^^^^^^^^^^^^^^^^^^^^^^^^^^^^^
  File "/home/alain/anaconda3/lib/python3.12/site-packages/django/views/generic/base.py", line 104, in view
    return self.dispatch(request, *args, **kwargs)
           ^^^^^^^^^^^^^^^^^^^^^^^^^^^^^^^^^^^^^^^
  File "/home/alain/anaconda3/lib/python3.12/site-packages/rest_framework/views.py", line 509, in dispatch
    response = self.handle_exception(exc)
               ^^^^^^^^^^^^^^^^^^^^^^^^^^
  File "/home/alain/anaconda3/lib/python3.12/site-packages/rest_framework/views.py", line 469, in handle_exception
    self.raise_uncaught_exception(exc)
  File "/home/alain/anaconda3/lib/python3.12/site-packages/rest_framework/views.py", line 480, in raise_uncaught_exception
    raise exc
  File "/home/alain/anaconda3/lib/python3.12/site-packages/rest_framework/views.py", line 506, in dispatch
    response = handler(request, *args, **kwargs)
               ^^^^^^^^^^^^^^^^^^^^^^^^^^^^^^^^^
  File "/home/alain/Alain/mentorledInternship/mentorledProject/vector_interview_app/views.py", line 12, in post
    serializer.save()
  File "/home/alain/anaconda3/lib/python3.12/site-packages/rest_framework/serializers.py", line 208, in save
    self.instance = self.create(validated_data)
                    ^^^^^^^^^^^^^^^^^^^^^^^^^^^
  File "/home/alain/anaconda3/lib/python3.12/site-packages/rest_framework/serializers.py", line 1008, in create
    raise TypeError(msg)
TypeError: Got a `TypeError` when calling `VectorUser.objects.create()`. This may be because you have a writable field on the serializer class that is not a valid argument to `VectorUser.objects.create()`. You may need to make the field read-only, or override the UserSignUpSerializer.create() method to handle this correctly.
Original exception was:
 Traceback (most recent call last):
  File "/home/alain/anaconda3/lib/python3.12/site-packages/rest_framework/serializers.py", line 989, in create
    instance = ModelClass._default_manager.create(**validated_data)
               ^^^^^^^^^^^^^^^^^^^^^^^^^^^^^^^^^^^^^^^^^^^^^^^^^^^^
  File "/home/alain/anaconda3/lib/python3.12/site-packages/django/db/models/manager.py", line 87, in manager_method
    return getattr(self.get_queryset(), name)(*args, **kwargs)
           ^^^^^^^^^^^^^^^^^^^^^^^^^^^^^^^^^^^^^^^^^^^^^^^^^^^
  File "/home/alain/anaconda3/lib/python3.12/site-packages/django/db/models/query.py", line 677, in create
    obj = self.model(**kwargs)
          ^^^^^^^^^^^^^^^^^^^^
  File "/home/alain/anaconda3/lib/python3.12/site-packages/django/db/models/base.py", line 567, in __init__
    raise TypeError(
TypeError: VectorUser() got unexpected keyword arguments: 'password2'

ERROR 2025-03-10 23:25:44,107 log Internal Server Error: /auth/signup/
Traceback (most recent call last):
  File "/home/alain/anaconda3/lib/python3.12/site-packages/rest_framework/serializers.py", line 989, in create
    instance = ModelClass._default_manager.create(**validated_data)
               ^^^^^^^^^^^^^^^^^^^^^^^^^^^^^^^^^^^^^^^^^^^^^^^^^^^^
  File "/home/alain/anaconda3/lib/python3.12/site-packages/django/db/models/manager.py", line 87, in manager_method
    return getattr(self.get_queryset(), name)(*args, **kwargs)
           ^^^^^^^^^^^^^^^^^^^^^^^^^^^^^^^^^^^^^^^^^^^^^^^^^^^
  File "/home/alain/anaconda3/lib/python3.12/site-packages/django/db/models/query.py", line 677, in create
    obj = self.model(**kwargs)
          ^^^^^^^^^^^^^^^^^^^^
  File "/home/alain/anaconda3/lib/python3.12/site-packages/django/db/models/base.py", line 567, in __init__
    raise TypeError(
TypeError: VectorUser() got unexpected keyword arguments: 'password2'

During handling of the above exception, another exception occurred:

Traceback (most recent call last):
  File "/home/alain/anaconda3/lib/python3.12/site-packages/django/core/handlers/exception.py", line 55, in inner
    response = get_response(request)
               ^^^^^^^^^^^^^^^^^^^^^
  File "/home/alain/anaconda3/lib/python3.12/site-packages/django/core/handlers/base.py", line 197, in _get_response
    response = wrapped_callback(request, *callback_args, **callback_kwargs)
               ^^^^^^^^^^^^^^^^^^^^^^^^^^^^^^^^^^^^^^^^^^^^^^^^^^^^^^^^^^^^
  File "/home/alain/anaconda3/lib/python3.12/site-packages/django/views/decorators/csrf.py", line 65, in _view_wrapper
    return view_func(request, *args, **kwargs)
           ^^^^^^^^^^^^^^^^^^^^^^^^^^^^^^^^^^^
  File "/home/alain/anaconda3/lib/python3.12/site-packages/django/views/generic/base.py", line 104, in view
    return self.dispatch(request, *args, **kwargs)
           ^^^^^^^^^^^^^^^^^^^^^^^^^^^^^^^^^^^^^^^
  File "/home/alain/anaconda3/lib/python3.12/site-packages/rest_framework/views.py", line 509, in dispatch
    response = self.handle_exception(exc)
               ^^^^^^^^^^^^^^^^^^^^^^^^^^
  File "/home/alain/anaconda3/lib/python3.12/site-packages/rest_framework/views.py", line 469, in handle_exception
    self.raise_uncaught_exception(exc)
  File "/home/alain/anaconda3/lib/python3.12/site-packages/rest_framework/views.py", line 480, in raise_uncaught_exception
    raise exc
  File "/home/alain/anaconda3/lib/python3.12/site-packages/rest_framework/views.py", line 506, in dispatch
    response = handler(request, *args, **kwargs)
               ^^^^^^^^^^^^^^^^^^^^^^^^^^^^^^^^^
  File "/home/alain/Alain/mentorledInternship/mentorledProject/vector_interview_app/views.py", line 12, in post
    serializer.save()
  File "/home/alain/anaconda3/lib/python3.12/site-packages/rest_framework/serializers.py", line 208, in save
    self.instance = self.create(validated_data)
                    ^^^^^^^^^^^^^^^^^^^^^^^^^^^
  File "/home/alain/anaconda3/lib/python3.12/site-packages/rest_framework/serializers.py", line 1008, in create
    raise TypeError(msg)
TypeError: Got a `TypeError` when calling `VectorUser.objects.create()`. This may be because you have a writable field on the serializer class that is not a valid argument to `VectorUser.objects.create()`. You may need to make the field read-only, or override the UserSignUpSerializer.create() method to handle this correctly.
Original exception was:
 Traceback (most recent call last):
  File "/home/alain/anaconda3/lib/python3.12/site-packages/rest_framework/serializers.py", line 989, in create
    instance = ModelClass._default_manager.create(**validated_data)
               ^^^^^^^^^^^^^^^^^^^^^^^^^^^^^^^^^^^^^^^^^^^^^^^^^^^^
  File "/home/alain/anaconda3/lib/python3.12/site-packages/django/db/models/manager.py", line 87, in manager_method
    return getattr(self.get_queryset(), name)(*args, **kwargs)
           ^^^^^^^^^^^^^^^^^^^^^^^^^^^^^^^^^^^^^^^^^^^^^^^^^^^
  File "/home/alain/anaconda3/lib/python3.12/site-packages/django/db/models/query.py", line 677, in create
    obj = self.model(**kwargs)
          ^^^^^^^^^^^^^^^^^^^^
  File "/home/alain/anaconda3/lib/python3.12/site-packages/django/db/models/base.py", line 567, in __init__
    raise TypeError(
TypeError: VectorUser() got unexpected keyword arguments: 'password2'

ERROR 2025-03-10 23:25:44,112 log Internal Server Error: /auth/signup/
Traceback (most recent call last):
  File "/home/alain/anaconda3/lib/python3.12/site-packages/rest_framework/serializers.py", line 989, in create
    instance = ModelClass._default_manager.create(**validated_data)
               ^^^^^^^^^^^^^^^^^^^^^^^^^^^^^^^^^^^^^^^^^^^^^^^^^^^^
  File "/home/alain/anaconda3/lib/python3.12/site-packages/django/db/models/manager.py", line 87, in manager_method
    return getattr(self.get_queryset(), name)(*args, **kwargs)
           ^^^^^^^^^^^^^^^^^^^^^^^^^^^^^^^^^^^^^^^^^^^^^^^^^^^
  File "/home/alain/anaconda3/lib/python3.12/site-packages/django/db/models/query.py", line 677, in create
    obj = self.model(**kwargs)
          ^^^^^^^^^^^^^^^^^^^^
  File "/home/alain/anaconda3/lib/python3.12/site-packages/django/db/models/base.py", line 567, in __init__
    raise TypeError(
TypeError: VectorUser() got unexpected keyword arguments: 'password2'

During handling of the above exception, another exception occurred:

Traceback (most recent call last):
  File "/home/alain/anaconda3/lib/python3.12/site-packages/django/core/handlers/exception.py", line 55, in inner
    response = get_response(request)
               ^^^^^^^^^^^^^^^^^^^^^
  File "/home/alain/anaconda3/lib/python3.12/site-packages/django/core/handlers/base.py", line 197, in _get_response
    response = wrapped_callback(request, *callback_args, **callback_kwargs)
               ^^^^^^^^^^^^^^^^^^^^^^^^^^^^^^^^^^^^^^^^^^^^^^^^^^^^^^^^^^^^
  File "/home/alain/anaconda3/lib/python3.12/site-packages/django/views/decorators/csrf.py", line 65, in _view_wrapper
    return view_func(request, *args, **kwargs)
           ^^^^^^^^^^^^^^^^^^^^^^^^^^^^^^^^^^^
  File "/home/alain/anaconda3/lib/python3.12/site-packages/django/views/generic/base.py", line 104, in view
    return self.dispatch(request, *args, **kwargs)
           ^^^^^^^^^^^^^^^^^^^^^^^^^^^^^^^^^^^^^^^
  File "/home/alain/anaconda3/lib/python3.12/site-packages/rest_framework/views.py", line 509, in dispatch
    response = self.handle_exception(exc)
               ^^^^^^^^^^^^^^^^^^^^^^^^^^
  File "/home/alain/anaconda3/lib/python3.12/site-packages/rest_framework/views.py", line 469, in handle_exception
    self.raise_uncaught_exception(exc)
  File "/home/alain/anaconda3/lib/python3.12/site-packages/rest_framework/views.py", line 480, in raise_uncaught_exception
    raise exc
  File "/home/alain/anaconda3/lib/python3.12/site-packages/rest_framework/views.py", line 506, in dispatch
    response = handler(request, *args, **kwargs)
               ^^^^^^^^^^^^^^^^^^^^^^^^^^^^^^^^^
  File "/home/alain/Alain/mentorledInternship/mentorledProject/vector_interview_app/views.py", line 12, in post
    serializer.save()
  File "/home/alain/anaconda3/lib/python3.12/site-packages/rest_framework/serializers.py", line 208, in save
    self.instance = self.create(validated_data)
                    ^^^^^^^^^^^^^^^^^^^^^^^^^^^
  File "/home/alain/anaconda3/lib/python3.12/site-packages/rest_framework/serializers.py", line 1008, in create
    raise TypeError(msg)
TypeError: Got a `TypeError` when calling `VectorUser.objects.create()`. This may be because you have a writable field on the serializer class that is not a valid argument to `VectorUser.objects.create()`. You may need to make the field read-only, or override the UserSignUpSerializer.create() method to handle this correctly.
Original exception was:
 Traceback (most recent call last):
  File "/home/alain/anaconda3/lib/python3.12/site-packages/rest_framework/serializers.py", line 989, in create
    instance = ModelClass._default_manager.create(**validated_data)
               ^^^^^^^^^^^^^^^^^^^^^^^^^^^^^^^^^^^^^^^^^^^^^^^^^^^^
  File "/home/alain/anaconda3/lib/python3.12/site-packages/django/db/models/manager.py", line 87, in manager_method
    return getattr(self.get_queryset(), name)(*args, **kwargs)
           ^^^^^^^^^^^^^^^^^^^^^^^^^^^^^^^^^^^^^^^^^^^^^^^^^^^
  File "/home/alain/anaconda3/lib/python3.12/site-packages/django/db/models/query.py", line 677, in create
    obj = self.model(**kwargs)
          ^^^^^^^^^^^^^^^^^^^^
  File "/home/alain/anaconda3/lib/python3.12/site-packages/django/db/models/base.py", line 567, in __init__
    raise TypeError(
TypeError: VectorUser() got unexpected keyword arguments: 'password2'

ERROR 2025-03-10 23:25:44,116 log Internal Server Error: /auth/signup/
Traceback (most recent call last):
  File "/home/alain/anaconda3/lib/python3.12/site-packages/rest_framework/serializers.py", line 989, in create
    instance = ModelClass._default_manager.create(**validated_data)
               ^^^^^^^^^^^^^^^^^^^^^^^^^^^^^^^^^^^^^^^^^^^^^^^^^^^^
  File "/home/alain/anaconda3/lib/python3.12/site-packages/django/db/models/manager.py", line 87, in manager_method
    return getattr(self.get_queryset(), name)(*args, **kwargs)
           ^^^^^^^^^^^^^^^^^^^^^^^^^^^^^^^^^^^^^^^^^^^^^^^^^^^
  File "/home/alain/anaconda3/lib/python3.12/site-packages/django/db/models/query.py", line 677, in create
    obj = self.model(**kwargs)
          ^^^^^^^^^^^^^^^^^^^^
  File "/home/alain/anaconda3/lib/python3.12/site-packages/django/db/models/base.py", line 567, in __init__
    raise TypeError(
TypeError: VectorUser() got unexpected keyword arguments: 'password2'

During handling of the above exception, another exception occurred:

Traceback (most recent call last):
  File "/home/alain/anaconda3/lib/python3.12/site-packages/django/core/handlers/exception.py", line 55, in inner
    response = get_response(request)
               ^^^^^^^^^^^^^^^^^^^^^
  File "/home/alain/anaconda3/lib/python3.12/site-packages/django/core/handlers/base.py", line 197, in _get_response
    response = wrapped_callback(request, *callback_args, **callback_kwargs)
               ^^^^^^^^^^^^^^^^^^^^^^^^^^^^^^^^^^^^^^^^^^^^^^^^^^^^^^^^^^^^
  File "/home/alain/anaconda3/lib/python3.12/site-packages/django/views/decorators/csrf.py", line 65, in _view_wrapper
    return view_func(request, *args, **kwargs)
           ^^^^^^^^^^^^^^^^^^^^^^^^^^^^^^^^^^^
  File "/home/alain/anaconda3/lib/python3.12/site-packages/django/views/generic/base.py", line 104, in view
    return self.dispatch(request, *args, **kwargs)
           ^^^^^^^^^^^^^^^^^^^^^^^^^^^^^^^^^^^^^^^
  File "/home/alain/anaconda3/lib/python3.12/site-packages/rest_framework/views.py", line 509, in dispatch
    response = self.handle_exception(exc)
               ^^^^^^^^^^^^^^^^^^^^^^^^^^
  File "/home/alain/anaconda3/lib/python3.12/site-packages/rest_framework/views.py", line 469, in handle_exception
    self.raise_uncaught_exception(exc)
  File "/home/alain/anaconda3/lib/python3.12/site-packages/rest_framework/views.py", line 480, in raise_uncaught_exception
    raise exc
  File "/home/alain/anaconda3/lib/python3.12/site-packages/rest_framework/views.py", line 506, in dispatch
    response = handler(request, *args, **kwargs)
               ^^^^^^^^^^^^^^^^^^^^^^^^^^^^^^^^^
  File "/home/alain/Alain/mentorledInternship/mentorledProject/vector_interview_app/views.py", line 12, in post
    serializer.save()
  File "/home/alain/anaconda3/lib/python3.12/site-packages/rest_framework/serializers.py", line 208, in save
    self.instance = self.create(validated_data)
                    ^^^^^^^^^^^^^^^^^^^^^^^^^^^
  File "/home/alain/anaconda3/lib/python3.12/site-packages/rest_framework/serializers.py", line 1008, in create
    raise TypeError(msg)
TypeError: Got a `TypeError` when calling `VectorUser.objects.create()`. This may be because you have a writable field on the serializer class that is not a valid argument to `VectorUser.objects.create()`. You may need to make the field read-only, or override the UserSignUpSerializer.create() method to handle this correctly.
Original exception was:
 Traceback (most recent call last):
  File "/home/alain/anaconda3/lib/python3.12/site-packages/rest_framework/serializers.py", line 989, in create
    instance = ModelClass._default_manager.create(**validated_data)
               ^^^^^^^^^^^^^^^^^^^^^^^^^^^^^^^^^^^^^^^^^^^^^^^^^^^^
  File "/home/alain/anaconda3/lib/python3.12/site-packages/django/db/models/manager.py", line 87, in manager_method
    return getattr(self.get_queryset(), name)(*args, **kwargs)
           ^^^^^^^^^^^^^^^^^^^^^^^^^^^^^^^^^^^^^^^^^^^^^^^^^^^
  File "/home/alain/anaconda3/lib/python3.12/site-packages/django/db/models/query.py", line 677, in create
    obj = self.model(**kwargs)
          ^^^^^^^^^^^^^^^^^^^^
  File "/home/alain/anaconda3/lib/python3.12/site-packages/django/db/models/base.py", line 567, in __init__
    raise TypeError(
TypeError: VectorUser() got unexpected keyword arguments: 'password2'

ERROR 2025-03-10 23:30:14,099 log Internal Server Error: /auth/signup/
Traceback (most recent call last):
  File "/home/alain/anaconda3/lib/python3.12/site-packages/rest_framework/serializers.py", line 989, in create
    instance = ModelClass._default_manager.create(**validated_data)
               ^^^^^^^^^^^^^^^^^^^^^^^^^^^^^^^^^^^^^^^^^^^^^^^^^^^^
  File "/home/alain/anaconda3/lib/python3.12/site-packages/django/db/models/manager.py", line 87, in manager_method
    return getattr(self.get_queryset(), name)(*args, **kwargs)
           ^^^^^^^^^^^^^^^^^^^^^^^^^^^^^^^^^^^^^^^^^^^^^^^^^^^
  File "/home/alain/anaconda3/lib/python3.12/site-packages/django/db/models/query.py", line 677, in create
    obj = self.model(**kwargs)
          ^^^^^^^^^^^^^^^^^^^^
  File "/home/alain/anaconda3/lib/python3.12/site-packages/django/db/models/base.py", line 567, in __init__
    raise TypeError(
TypeError: VectorUser() got unexpected keyword arguments: 'password2'

During handling of the above exception, another exception occurred:

Traceback (most recent call last):
  File "/home/alain/anaconda3/lib/python3.12/site-packages/django/core/handlers/exception.py", line 55, in inner
    response = get_response(request)
               ^^^^^^^^^^^^^^^^^^^^^
  File "/home/alain/anaconda3/lib/python3.12/site-packages/django/core/handlers/base.py", line 197, in _get_response
    response = wrapped_callback(request, *callback_args, **callback_kwargs)
               ^^^^^^^^^^^^^^^^^^^^^^^^^^^^^^^^^^^^^^^^^^^^^^^^^^^^^^^^^^^^
  File "/home/alain/anaconda3/lib/python3.12/site-packages/django/views/decorators/csrf.py", line 65, in _view_wrapper
    return view_func(request, *args, **kwargs)
           ^^^^^^^^^^^^^^^^^^^^^^^^^^^^^^^^^^^
  File "/home/alain/anaconda3/lib/python3.12/site-packages/django/views/generic/base.py", line 104, in view
    return self.dispatch(request, *args, **kwargs)
           ^^^^^^^^^^^^^^^^^^^^^^^^^^^^^^^^^^^^^^^
  File "/home/alain/anaconda3/lib/python3.12/site-packages/rest_framework/views.py", line 509, in dispatch
    response = self.handle_exception(exc)
               ^^^^^^^^^^^^^^^^^^^^^^^^^^
  File "/home/alain/anaconda3/lib/python3.12/site-packages/rest_framework/views.py", line 469, in handle_exception
    self.raise_uncaught_exception(exc)
  File "/home/alain/anaconda3/lib/python3.12/site-packages/rest_framework/views.py", line 480, in raise_uncaught_exception
    raise exc
  File "/home/alain/anaconda3/lib/python3.12/site-packages/rest_framework/views.py", line 506, in dispatch
    response = handler(request, *args, **kwargs)
               ^^^^^^^^^^^^^^^^^^^^^^^^^^^^^^^^^
  File "/home/alain/Alain/mentorledInternship/mentorledProject/vector_interview_app/views.py", line 12, in post
    serializer.save()
  File "/home/alain/anaconda3/lib/python3.12/site-packages/rest_framework/serializers.py", line 208, in save
    self.instance = self.create(validated_data)
                    ^^^^^^^^^^^^^^^^^^^^^^^^^^^
  File "/home/alain/anaconda3/lib/python3.12/site-packages/rest_framework/serializers.py", line 1008, in create
    raise TypeError(msg)
TypeError: Got a `TypeError` when calling `VectorUser.objects.create()`. This may be because you have a writable field on the serializer class that is not a valid argument to `VectorUser.objects.create()`. You may need to make the field read-only, or override the UserSignUpSerializer.create() method to handle this correctly.
Original exception was:
 Traceback (most recent call last):
  File "/home/alain/anaconda3/lib/python3.12/site-packages/rest_framework/serializers.py", line 989, in create
    instance = ModelClass._default_manager.create(**validated_data)
               ^^^^^^^^^^^^^^^^^^^^^^^^^^^^^^^^^^^^^^^^^^^^^^^^^^^^
  File "/home/alain/anaconda3/lib/python3.12/site-packages/django/db/models/manager.py", line 87, in manager_method
    return getattr(self.get_queryset(), name)(*args, **kwargs)
           ^^^^^^^^^^^^^^^^^^^^^^^^^^^^^^^^^^^^^^^^^^^^^^^^^^^
  File "/home/alain/anaconda3/lib/python3.12/site-packages/django/db/models/query.py", line 677, in create
    obj = self.model(**kwargs)
          ^^^^^^^^^^^^^^^^^^^^
  File "/home/alain/anaconda3/lib/python3.12/site-packages/django/db/models/base.py", line 567, in __init__
    raise TypeError(
TypeError: VectorUser() got unexpected keyword arguments: 'password2'

ERROR 2025-03-10 23:30:14,106 log Internal Server Error: /auth/signup/
Traceback (most recent call last):
  File "/home/alain/anaconda3/lib/python3.12/site-packages/rest_framework/serializers.py", line 989, in create
    instance = ModelClass._default_manager.create(**validated_data)
               ^^^^^^^^^^^^^^^^^^^^^^^^^^^^^^^^^^^^^^^^^^^^^^^^^^^^
  File "/home/alain/anaconda3/lib/python3.12/site-packages/django/db/models/manager.py", line 87, in manager_method
    return getattr(self.get_queryset(), name)(*args, **kwargs)
           ^^^^^^^^^^^^^^^^^^^^^^^^^^^^^^^^^^^^^^^^^^^^^^^^^^^
  File "/home/alain/anaconda3/lib/python3.12/site-packages/django/db/models/query.py", line 677, in create
    obj = self.model(**kwargs)
          ^^^^^^^^^^^^^^^^^^^^
  File "/home/alain/anaconda3/lib/python3.12/site-packages/django/db/models/base.py", line 567, in __init__
    raise TypeError(
TypeError: VectorUser() got unexpected keyword arguments: 'password2'

During handling of the above exception, another exception occurred:

Traceback (most recent call last):
  File "/home/alain/anaconda3/lib/python3.12/site-packages/django/core/handlers/exception.py", line 55, in inner
    response = get_response(request)
               ^^^^^^^^^^^^^^^^^^^^^
  File "/home/alain/anaconda3/lib/python3.12/site-packages/django/core/handlers/base.py", line 197, in _get_response
    response = wrapped_callback(request, *callback_args, **callback_kwargs)
               ^^^^^^^^^^^^^^^^^^^^^^^^^^^^^^^^^^^^^^^^^^^^^^^^^^^^^^^^^^^^
  File "/home/alain/anaconda3/lib/python3.12/site-packages/django/views/decorators/csrf.py", line 65, in _view_wrapper
    return view_func(request, *args, **kwargs)
           ^^^^^^^^^^^^^^^^^^^^^^^^^^^^^^^^^^^
  File "/home/alain/anaconda3/lib/python3.12/site-packages/django/views/generic/base.py", line 104, in view
    return self.dispatch(request, *args, **kwargs)
           ^^^^^^^^^^^^^^^^^^^^^^^^^^^^^^^^^^^^^^^
  File "/home/alain/anaconda3/lib/python3.12/site-packages/rest_framework/views.py", line 509, in dispatch
    response = self.handle_exception(exc)
               ^^^^^^^^^^^^^^^^^^^^^^^^^^
  File "/home/alain/anaconda3/lib/python3.12/site-packages/rest_framework/views.py", line 469, in handle_exception
    self.raise_uncaught_exception(exc)
  File "/home/alain/anaconda3/lib/python3.12/site-packages/rest_framework/views.py", line 480, in raise_uncaught_exception
    raise exc
  File "/home/alain/anaconda3/lib/python3.12/site-packages/rest_framework/views.py", line 506, in dispatch
    response = handler(request, *args, **kwargs)
               ^^^^^^^^^^^^^^^^^^^^^^^^^^^^^^^^^
  File "/home/alain/Alain/mentorledInternship/mentorledProject/vector_interview_app/views.py", line 12, in post
    serializer.save()
  File "/home/alain/anaconda3/lib/python3.12/site-packages/rest_framework/serializers.py", line 208, in save
    self.instance = self.create(validated_data)
                    ^^^^^^^^^^^^^^^^^^^^^^^^^^^
  File "/home/alain/anaconda3/lib/python3.12/site-packages/rest_framework/serializers.py", line 1008, in create
    raise TypeError(msg)
TypeError: Got a `TypeError` when calling `VectorUser.objects.create()`. This may be because you have a writable field on the serializer class that is not a valid argument to `VectorUser.objects.create()`. You may need to make the field read-only, or override the UserSignUpSerializer.create() method to handle this correctly.
Original exception was:
 Traceback (most recent call last):
  File "/home/alain/anaconda3/lib/python3.12/site-packages/rest_framework/serializers.py", line 989, in create
    instance = ModelClass._default_manager.create(**validated_data)
               ^^^^^^^^^^^^^^^^^^^^^^^^^^^^^^^^^^^^^^^^^^^^^^^^^^^^
  File "/home/alain/anaconda3/lib/python3.12/site-packages/django/db/models/manager.py", line 87, in manager_method
    return getattr(self.get_queryset(), name)(*args, **kwargs)
           ^^^^^^^^^^^^^^^^^^^^^^^^^^^^^^^^^^^^^^^^^^^^^^^^^^^
  File "/home/alain/anaconda3/lib/python3.12/site-packages/django/db/models/query.py", line 677, in create
    obj = self.model(**kwargs)
          ^^^^^^^^^^^^^^^^^^^^
  File "/home/alain/anaconda3/lib/python3.12/site-packages/django/db/models/base.py", line 567, in __init__
    raise TypeError(
TypeError: VectorUser() got unexpected keyword arguments: 'password2'

ERROR 2025-03-10 23:30:14,111 log Internal Server Error: /auth/signup/
Traceback (most recent call last):
  File "/home/alain/anaconda3/lib/python3.12/site-packages/rest_framework/serializers.py", line 989, in create
    instance = ModelClass._default_manager.create(**validated_data)
               ^^^^^^^^^^^^^^^^^^^^^^^^^^^^^^^^^^^^^^^^^^^^^^^^^^^^
  File "/home/alain/anaconda3/lib/python3.12/site-packages/django/db/models/manager.py", line 87, in manager_method
    return getattr(self.get_queryset(), name)(*args, **kwargs)
           ^^^^^^^^^^^^^^^^^^^^^^^^^^^^^^^^^^^^^^^^^^^^^^^^^^^
  File "/home/alain/anaconda3/lib/python3.12/site-packages/django/db/models/query.py", line 677, in create
    obj = self.model(**kwargs)
          ^^^^^^^^^^^^^^^^^^^^
  File "/home/alain/anaconda3/lib/python3.12/site-packages/django/db/models/base.py", line 567, in __init__
    raise TypeError(
TypeError: VectorUser() got unexpected keyword arguments: 'password2'

During handling of the above exception, another exception occurred:

Traceback (most recent call last):
  File "/home/alain/anaconda3/lib/python3.12/site-packages/django/core/handlers/exception.py", line 55, in inner
    response = get_response(request)
               ^^^^^^^^^^^^^^^^^^^^^
  File "/home/alain/anaconda3/lib/python3.12/site-packages/django/core/handlers/base.py", line 197, in _get_response
    response = wrapped_callback(request, *callback_args, **callback_kwargs)
               ^^^^^^^^^^^^^^^^^^^^^^^^^^^^^^^^^^^^^^^^^^^^^^^^^^^^^^^^^^^^
  File "/home/alain/anaconda3/lib/python3.12/site-packages/django/views/decorators/csrf.py", line 65, in _view_wrapper
    return view_func(request, *args, **kwargs)
           ^^^^^^^^^^^^^^^^^^^^^^^^^^^^^^^^^^^
  File "/home/alain/anaconda3/lib/python3.12/site-packages/django/views/generic/base.py", line 104, in view
    return self.dispatch(request, *args, **kwargs)
           ^^^^^^^^^^^^^^^^^^^^^^^^^^^^^^^^^^^^^^^
  File "/home/alain/anaconda3/lib/python3.12/site-packages/rest_framework/views.py", line 509, in dispatch
    response = self.handle_exception(exc)
               ^^^^^^^^^^^^^^^^^^^^^^^^^^
  File "/home/alain/anaconda3/lib/python3.12/site-packages/rest_framework/views.py", line 469, in handle_exception
    self.raise_uncaught_exception(exc)
  File "/home/alain/anaconda3/lib/python3.12/site-packages/rest_framework/views.py", line 480, in raise_uncaught_exception
    raise exc
  File "/home/alain/anaconda3/lib/python3.12/site-packages/rest_framework/views.py", line 506, in dispatch
    response = handler(request, *args, **kwargs)
               ^^^^^^^^^^^^^^^^^^^^^^^^^^^^^^^^^
  File "/home/alain/Alain/mentorledInternship/mentorledProject/vector_interview_app/views.py", line 12, in post
    serializer.save()
  File "/home/alain/anaconda3/lib/python3.12/site-packages/rest_framework/serializers.py", line 208, in save
    self.instance = self.create(validated_data)
                    ^^^^^^^^^^^^^^^^^^^^^^^^^^^
  File "/home/alain/anaconda3/lib/python3.12/site-packages/rest_framework/serializers.py", line 1008, in create
    raise TypeError(msg)
TypeError: Got a `TypeError` when calling `VectorUser.objects.create()`. This may be because you have a writable field on the serializer class that is not a valid argument to `VectorUser.objects.create()`. You may need to make the field read-only, or override the UserSignUpSerializer.create() method to handle this correctly.
Original exception was:
 Traceback (most recent call last):
  File "/home/alain/anaconda3/lib/python3.12/site-packages/rest_framework/serializers.py", line 989, in create
    instance = ModelClass._default_manager.create(**validated_data)
               ^^^^^^^^^^^^^^^^^^^^^^^^^^^^^^^^^^^^^^^^^^^^^^^^^^^^
  File "/home/alain/anaconda3/lib/python3.12/site-packages/django/db/models/manager.py", line 87, in manager_method
    return getattr(self.get_queryset(), name)(*args, **kwargs)
           ^^^^^^^^^^^^^^^^^^^^^^^^^^^^^^^^^^^^^^^^^^^^^^^^^^^
  File "/home/alain/anaconda3/lib/python3.12/site-packages/django/db/models/query.py", line 677, in create
    obj = self.model(**kwargs)
          ^^^^^^^^^^^^^^^^^^^^
  File "/home/alain/anaconda3/lib/python3.12/site-packages/django/db/models/base.py", line 567, in __init__
    raise TypeError(
TypeError: VectorUser() got unexpected keyword arguments: 'password2'

ERROR 2025-03-10 23:30:14,115 log Internal Server Error: /auth/signup/
Traceback (most recent call last):
  File "/home/alain/anaconda3/lib/python3.12/site-packages/rest_framework/serializers.py", line 989, in create
    instance = ModelClass._default_manager.create(**validated_data)
               ^^^^^^^^^^^^^^^^^^^^^^^^^^^^^^^^^^^^^^^^^^^^^^^^^^^^
  File "/home/alain/anaconda3/lib/python3.12/site-packages/django/db/models/manager.py", line 87, in manager_method
    return getattr(self.get_queryset(), name)(*args, **kwargs)
           ^^^^^^^^^^^^^^^^^^^^^^^^^^^^^^^^^^^^^^^^^^^^^^^^^^^
  File "/home/alain/anaconda3/lib/python3.12/site-packages/django/db/models/query.py", line 677, in create
    obj = self.model(**kwargs)
          ^^^^^^^^^^^^^^^^^^^^
  File "/home/alain/anaconda3/lib/python3.12/site-packages/django/db/models/base.py", line 567, in __init__
    raise TypeError(
TypeError: VectorUser() got unexpected keyword arguments: 'password2'

During handling of the above exception, another exception occurred:

Traceback (most recent call last):
  File "/home/alain/anaconda3/lib/python3.12/site-packages/django/core/handlers/exception.py", line 55, in inner
    response = get_response(request)
               ^^^^^^^^^^^^^^^^^^^^^
  File "/home/alain/anaconda3/lib/python3.12/site-packages/django/core/handlers/base.py", line 197, in _get_response
    response = wrapped_callback(request, *callback_args, **callback_kwargs)
               ^^^^^^^^^^^^^^^^^^^^^^^^^^^^^^^^^^^^^^^^^^^^^^^^^^^^^^^^^^^^
  File "/home/alain/anaconda3/lib/python3.12/site-packages/django/views/decorators/csrf.py", line 65, in _view_wrapper
    return view_func(request, *args, **kwargs)
           ^^^^^^^^^^^^^^^^^^^^^^^^^^^^^^^^^^^
  File "/home/alain/anaconda3/lib/python3.12/site-packages/django/views/generic/base.py", line 104, in view
    return self.dispatch(request, *args, **kwargs)
           ^^^^^^^^^^^^^^^^^^^^^^^^^^^^^^^^^^^^^^^
  File "/home/alain/anaconda3/lib/python3.12/site-packages/rest_framework/views.py", line 509, in dispatch
    response = self.handle_exception(exc)
               ^^^^^^^^^^^^^^^^^^^^^^^^^^
  File "/home/alain/anaconda3/lib/python3.12/site-packages/rest_framework/views.py", line 469, in handle_exception
    self.raise_uncaught_exception(exc)
  File "/home/alain/anaconda3/lib/python3.12/site-packages/rest_framework/views.py", line 480, in raise_uncaught_exception
    raise exc
  File "/home/alain/anaconda3/lib/python3.12/site-packages/rest_framework/views.py", line 506, in dispatch
    response = handler(request, *args, **kwargs)
               ^^^^^^^^^^^^^^^^^^^^^^^^^^^^^^^^^
  File "/home/alain/Alain/mentorledInternship/mentorledProject/vector_interview_app/views.py", line 12, in post
    serializer.save()
  File "/home/alain/anaconda3/lib/python3.12/site-packages/rest_framework/serializers.py", line 208, in save
    self.instance = self.create(validated_data)
                    ^^^^^^^^^^^^^^^^^^^^^^^^^^^
  File "/home/alain/anaconda3/lib/python3.12/site-packages/rest_framework/serializers.py", line 1008, in create
    raise TypeError(msg)
TypeError: Got a `TypeError` when calling `VectorUser.objects.create()`. This may be because you have a writable field on the serializer class that is not a valid argument to `VectorUser.objects.create()`. You may need to make the field read-only, or override the UserSignUpSerializer.create() method to handle this correctly.
Original exception was:
 Traceback (most recent call last):
  File "/home/alain/anaconda3/lib/python3.12/site-packages/rest_framework/serializers.py", line 989, in create
    instance = ModelClass._default_manager.create(**validated_data)
               ^^^^^^^^^^^^^^^^^^^^^^^^^^^^^^^^^^^^^^^^^^^^^^^^^^^^
  File "/home/alain/anaconda3/lib/python3.12/site-packages/django/db/models/manager.py", line 87, in manager_method
    return getattr(self.get_queryset(), name)(*args, **kwargs)
           ^^^^^^^^^^^^^^^^^^^^^^^^^^^^^^^^^^^^^^^^^^^^^^^^^^^
  File "/home/alain/anaconda3/lib/python3.12/site-packages/django/db/models/query.py", line 677, in create
    obj = self.model(**kwargs)
          ^^^^^^^^^^^^^^^^^^^^
  File "/home/alain/anaconda3/lib/python3.12/site-packages/django/db/models/base.py", line 567, in __init__
    raise TypeError(
TypeError: VectorUser() got unexpected keyword arguments: 'password2'

WARNING 2025-03-10 23:52:08,262 log Bad Request: /auth/signup/
WARNING 2025-03-10 23:54:45,810 log Not Found: /
WARNING 2025-03-10 23:54:45,811 basehttp "GET / HTTP/1.1" 404 2315
WARNING 2025-03-10 23:54:47,037 log Not Found: /favicon.ico
WARNING 2025-03-10 23:54:47,037 basehttp "GET /favicon.ico HTTP/1.1" 404 2366
WARNING 2025-03-10 23:55:21,641 log Method Not Allowed: /auth/signup/
WARNING 2025-03-10 23:55:21,641 basehttp "GET /auth/signup/ HTTP/1.1" 405 12954
WARNING 2025-03-10 23:55:21,849 log Not Found: /favicon.ico
WARNING 2025-03-10 23:55:21,849 basehttp "GET /favicon.ico HTTP/1.1" 404 2366
WARNING 2025-03-10 23:57:01,821 log Method Not Allowed: /auth/login/
WARNING 2025-03-10 23:57:01,821 basehttp "GET /auth/login/ HTTP/1.1" 405 12442
WARNING 2025-03-10 23:57:01,891 log Not Found: /favicon.ico
ERROR 2025-03-11 00:58:16,869 log Internal Server Error: /auth/signup/
Traceback (most recent call last):
  File "/home/alain/anaconda3/lib/python3.12/site-packages/django/core/handlers/exception.py", line 55, in inner
    response = get_response(request)
               ^^^^^^^^^^^^^^^^^^^^^
  File "/home/alain/anaconda3/lib/python3.12/site-packages/django/core/handlers/base.py", line 220, in _get_response
    response = response.render()
               ^^^^^^^^^^^^^^^^^
  File "/home/alain/anaconda3/lib/python3.12/site-packages/django/template/response.py", line 114, in render
    self.content = self.rendered_content
                   ^^^^^^^^^^^^^^^^^^^^^
  File "/home/alain/anaconda3/lib/python3.12/site-packages/rest_framework/response.py", line 74, in rendered_content
    ret = renderer.render(self.data, accepted_media_type, context)
          ^^^^^^^^^^^^^^^^^^^^^^^^^^^^^^^^^^^^^^^^^^^^^^^^^^^^^^^^
  File "/home/alain/anaconda3/lib/python3.12/site-packages/rest_framework/renderers.py", line 160, in render
    template = self.resolve_template(template_names)
               ^^^^^^^^^^^^^^^^^^^^^^^^^^^^^^^^^^^^^
  File "/home/alain/anaconda3/lib/python3.12/site-packages/rest_framework/renderers.py", line 170, in resolve_template
    return loader.select_template(template_names)
           ^^^^^^^^^^^^^^^^^^^^^^^^^^^^^^^^^^^^^^
  File "/home/alain/anaconda3/lib/python3.12/site-packages/django/template/loader.py", line 47, in select_template
    raise TemplateDoesNotExist(", ".join(template_name_list), chain=chain)
django.template.exceptions.TemplateDoesNotExist: signup.html
ERROR 2025-03-11 00:58:16,871 basehttp "GET /auth/signup/ HTTP/1.1" 500 96892
ERROR 2025-03-11 01:02:08,390 log Internal Server Error: /auth/signup/
Traceback (most recent call last):
  File "/home/alain/anaconda3/lib/python3.12/site-packages/django/template/base.py", line 510, in parse
    compile_func = self.tags[command]
                   ~~~~~~~~~^^^^^^^^^
KeyError: 'static'

During handling of the above exception, another exception occurred:

Traceback (most recent call last):
  File "/home/alain/anaconda3/lib/python3.12/site-packages/django/core/handlers/exception.py", line 55, in inner
    response = get_response(request)
               ^^^^^^^^^^^^^^^^^^^^^
  File "/home/alain/anaconda3/lib/python3.12/site-packages/django/core/handlers/base.py", line 220, in _get_response
    response = response.render()
               ^^^^^^^^^^^^^^^^^
  File "/home/alain/anaconda3/lib/python3.12/site-packages/django/template/response.py", line 114, in render
    self.content = self.rendered_content
                   ^^^^^^^^^^^^^^^^^^^^^
  File "/home/alain/anaconda3/lib/python3.12/site-packages/rest_framework/response.py", line 74, in rendered_content
    ret = renderer.render(self.data, accepted_media_type, context)
          ^^^^^^^^^^^^^^^^^^^^^^^^^^^^^^^^^^^^^^^^^^^^^^^^^^^^^^^^
  File "/home/alain/anaconda3/lib/python3.12/site-packages/rest_framework/renderers.py", line 160, in render
    template = self.resolve_template(template_names)
               ^^^^^^^^^^^^^^^^^^^^^^^^^^^^^^^^^^^^^
  File "/home/alain/anaconda3/lib/python3.12/site-packages/rest_framework/renderers.py", line 170, in resolve_template
    return loader.select_template(template_names)
           ^^^^^^^^^^^^^^^^^^^^^^^^^^^^^^^^^^^^^^
  File "/home/alain/anaconda3/lib/python3.12/site-packages/django/template/loader.py", line 42, in select_template
    return engine.get_template(template_name)
           ^^^^^^^^^^^^^^^^^^^^^^^^^^^^^^^^^^
  File "/home/alain/anaconda3/lib/python3.12/site-packages/django/template/backends/django.py", line 79, in get_template
    return Template(self.engine.get_template(template_name), self)
                    ^^^^^^^^^^^^^^^^^^^^^^^^^^^^^^^^^^^^^^^
  File "/home/alain/anaconda3/lib/python3.12/site-packages/django/template/engine.py", line 177, in get_template
    template, origin = self.find_template(template_name)
                       ^^^^^^^^^^^^^^^^^^^^^^^^^^^^^^^^^
  File "/home/alain/anaconda3/lib/python3.12/site-packages/django/template/engine.py", line 159, in find_template
    template = loader.get_template(name, skip=skip)
               ^^^^^^^^^^^^^^^^^^^^^^^^^^^^^^^^^^^^
  File "/home/alain/anaconda3/lib/python3.12/site-packages/django/template/loaders/cached.py", line 57, in get_template
    template = super().get_template(template_name, skip)
               ^^^^^^^^^^^^^^^^^^^^^^^^^^^^^^^^^^^^^^^^^
  File "/home/alain/anaconda3/lib/python3.12/site-packages/django/template/loaders/base.py", line 28, in get_template
    return Template(
           ^^^^^^^^^
  File "/home/alain/anaconda3/lib/python3.12/site-packages/django/template/base.py", line 154, in __init__
    self.nodelist = self.compile_nodelist()
                    ^^^^^^^^^^^^^^^^^^^^^^^
  File "/home/alain/anaconda3/lib/python3.12/site-packages/django/template/base.py", line 196, in compile_nodelist
    nodelist = parser.parse()
               ^^^^^^^^^^^^^^
  File "/home/alain/anaconda3/lib/python3.12/site-packages/django/template/base.py", line 512, in parse
    self.invalid_block_tag(token, command, parse_until)
  File "/home/alain/anaconda3/lib/python3.12/site-packages/django/template/base.py", line 573, in invalid_block_tag
    raise self.error(
django.template.exceptions.TemplateSyntaxError: Invalid block tag on line 11: 'static'. Did you forget to register or load this tag?
ERROR 2025-03-11 01:02:08,391 basehttp "GET /auth/signup/ HTTP/1.1" 500 172959
ERROR 2025-03-11 01:03:20,316 log Internal Server Error: /auth/signup/
Traceback (most recent call last):
  File "/home/alain/anaconda3/lib/python3.12/site-packages/django/core/handlers/exception.py", line 55, in inner
    response = get_response(request)
               ^^^^^^^^^^^^^^^^^^^^^
  File "/home/alain/anaconda3/lib/python3.12/site-packages/django/core/handlers/base.py", line 220, in _get_response
    response = response.render()
               ^^^^^^^^^^^^^^^^^
  File "/home/alain/anaconda3/lib/python3.12/site-packages/django/template/response.py", line 114, in render
    self.content = self.rendered_content
                   ^^^^^^^^^^^^^^^^^^^^^
  File "/home/alain/anaconda3/lib/python3.12/site-packages/rest_framework/response.py", line 74, in rendered_content
    ret = renderer.render(self.data, accepted_media_type, context)
          ^^^^^^^^^^^^^^^^^^^^^^^^^^^^^^^^^^^^^^^^^^^^^^^^^^^^^^^^
  File "/home/alain/anaconda3/lib/python3.12/site-packages/rest_framework/renderers.py", line 167, in render
    return template.render(context, request=request)
           ^^^^^^^^^^^^^^^^^^^^^^^^^^^^^^^^^^^^^^^^^
  File "/home/alain/anaconda3/lib/python3.12/site-packages/django/template/backends/django.py", line 107, in render
    return self.template.render(context)
           ^^^^^^^^^^^^^^^^^^^^^^^^^^^^^
  File "/home/alain/anaconda3/lib/python3.12/site-packages/django/template/base.py", line 171, in render
    return self._render(context)
           ^^^^^^^^^^^^^^^^^^^^^
  File "/home/alain/anaconda3/lib/python3.12/site-packages/django/template/base.py", line 163, in _render
    return self.nodelist.render(context)
           ^^^^^^^^^^^^^^^^^^^^^^^^^^^^^
  File "/home/alain/anaconda3/lib/python3.12/site-packages/django/template/base.py", line 1008, in render
    return SafeString("".join([node.render_annotated(context) for node in self]))
                               ^^^^^^^^^^^^^^^^^^^^^^^^^^^^^^
  File "/home/alain/anaconda3/lib/python3.12/site-packages/django/template/base.py", line 969, in render_annotated
    return self.render(context)
           ^^^^^^^^^^^^^^^^^^^^
  File "/home/alain/anaconda3/lib/python3.12/site-packages/django/template/defaulttags.py", line 480, in render
    url = reverse(view_name, args=args, kwargs=kwargs, current_app=current_app)
          ^^^^^^^^^^^^^^^^^^^^^^^^^^^^^^^^^^^^^^^^^^^^^^^^^^^^^^^^^^^^^^^^^^^^^
  File "/home/alain/anaconda3/lib/python3.12/site-packages/django/urls/base.py", line 88, in reverse
    return resolver._reverse_with_prefix(view, prefix, *args, **kwargs)
           ^^^^^^^^^^^^^^^^^^^^^^^^^^^^^^^^^^^^^^^^^^^^^^^^^^^^^^^^^^^^
  File "/home/alain/anaconda3/lib/python3.12/site-packages/django/urls/resolvers.py", line 831, in _reverse_with_prefix
    raise NoReverseMatch(msg)
django.urls.exceptions.NoReverseMatch: Reverse for 'login' not found. 'login' is not a valid view function or pattern name.
ERROR 2025-03-11 01:03:20,317 basehttp "GET /auth/signup/ HTTP/1.1" 500 133916
ERROR 2025-03-11 01:27:54,959 log Internal Server Error: /auth/signup/
Traceback (most recent call last):
  File "/home/alain/anaconda3/lib/python3.12/site-packages/django/template/base.py", line 883, in _resolve_lookup
    current = current[bit]
              ~~~~~~~^^^^^
  File "/home/alain/anaconda3/lib/python3.12/site-packages/rest_framework/serializers.py", line 557, in __getitem__
    field = self.fields[key]
            ~~~~~~~~~~~^^^^^
  File "/home/alain/anaconda3/lib/python3.12/site-packages/rest_framework/utils/serializer_helpers.py", line 170, in __getitem__
    return self.fields[key]
           ~~~~~~~~~~~^^^^^
KeyError: 'errors'

During handling of the above exception, another exception occurred:

Traceback (most recent call last):
  File "/home/alain/anaconda3/lib/python3.12/site-packages/django/core/handlers/exception.py", line 55, in inner
    response = get_response(request)
               ^^^^^^^^^^^^^^^^^^^^^
  File "/home/alain/anaconda3/lib/python3.12/site-packages/django/core/handlers/base.py", line 220, in _get_response
    response = response.render()
               ^^^^^^^^^^^^^^^^^
  File "/home/alain/anaconda3/lib/python3.12/site-packages/django/template/response.py", line 114, in render
    self.content = self.rendered_content
                   ^^^^^^^^^^^^^^^^^^^^^
  File "/home/alain/anaconda3/lib/python3.12/site-packages/rest_framework/response.py", line 74, in rendered_content
    ret = renderer.render(self.data, accepted_media_type, context)
          ^^^^^^^^^^^^^^^^^^^^^^^^^^^^^^^^^^^^^^^^^^^^^^^^^^^^^^^^
  File "/home/alain/anaconda3/lib/python3.12/site-packages/rest_framework/renderers.py", line 167, in render
    return template.render(context, request=request)
           ^^^^^^^^^^^^^^^^^^^^^^^^^^^^^^^^^^^^^^^^^
  File "/home/alain/anaconda3/lib/python3.12/site-packages/django/template/backends/django.py", line 107, in render
    return self.template.render(context)
           ^^^^^^^^^^^^^^^^^^^^^^^^^^^^^
  File "/home/alain/anaconda3/lib/python3.12/site-packages/django/template/base.py", line 171, in render
    return self._render(context)
           ^^^^^^^^^^^^^^^^^^^^^
  File "/home/alain/anaconda3/lib/python3.12/site-packages/django/template/base.py", line 163, in _render
    return self.nodelist.render(context)
           ^^^^^^^^^^^^^^^^^^^^^^^^^^^^^
  File "/home/alain/anaconda3/lib/python3.12/site-packages/django/template/base.py", line 1008, in render
    return SafeString("".join([node.render_annotated(context) for node in self]))
                               ^^^^^^^^^^^^^^^^^^^^^^^^^^^^^^
  File "/home/alain/anaconda3/lib/python3.12/site-packages/django/template/base.py", line 969, in render_annotated
    return self.render(context)
           ^^^^^^^^^^^^^^^^^^^^
  File "/home/alain/anaconda3/lib/python3.12/site-packages/django/template/defaulttags.py", line 320, in render
    match = condition.eval(context)
            ^^^^^^^^^^^^^^^^^^^^^^^
  File "/home/alain/anaconda3/lib/python3.12/site-packages/django/template/defaulttags.py", line 886, in eval
    return self.value.resolve(context, ignore_failures=True)
           ^^^^^^^^^^^^^^^^^^^^^^^^^^^^^^^^^^^^^^^^^^^^^^^^^
  File "/home/alain/anaconda3/lib/python3.12/site-packages/django/template/base.py", line 718, in resolve
    obj = self.var.resolve(context)
          ^^^^^^^^^^^^^^^^^^^^^^^^^
  File "/home/alain/anaconda3/lib/python3.12/site-packages/django/template/base.py", line 850, in resolve
    value = self._resolve_lookup(context)
            ^^^^^^^^^^^^^^^^^^^^^^^^^^^^^
  File "/home/alain/anaconda3/lib/python3.12/site-packages/django/template/base.py", line 893, in _resolve_lookup
    current = getattr(current, bit)
              ^^^^^^^^^^^^^^^^^^^^^
  File "/home/alain/anaconda3/lib/python3.12/site-packages/rest_framework/serializers.py", line 576, in errors
    ret = super().errors
          ^^^^^^^^^^^^^^
  File "/home/alain/anaconda3/lib/python3.12/site-packages/rest_framework/serializers.py", line 260, in errors
    raise AssertionError(msg)
AssertionError: You must call `.is_valid()` before accessing `.errors`.
ERROR 2025-03-11 01:27:54,961 basehttp "GET /auth/signup/ HTTP/1.1" 500 165748
ERROR 2025-03-11 01:31:42,121 log Internal Server Error: /auth/signup/
Traceback (most recent call last):
  File "/home/alain/anaconda3/lib/python3.12/site-packages/django/template/base.py", line 883, in _resolve_lookup
    current = current[bit]
              ~~~~~~~^^^^^
  File "/home/alain/anaconda3/lib/python3.12/site-packages/rest_framework/serializers.py", line 557, in __getitem__
    field = self.fields[key]
            ~~~~~~~~~~~^^^^^
  File "/home/alain/anaconda3/lib/python3.12/site-packages/rest_framework/utils/serializer_helpers.py", line 170, in __getitem__
    return self.fields[key]
           ~~~~~~~~~~~^^^^^
KeyError: 'errors'

During handling of the above exception, another exception occurred:

Traceback (most recent call last):
  File "/home/alain/anaconda3/lib/python3.12/site-packages/django/core/handlers/exception.py", line 55, in inner
    response = get_response(request)
               ^^^^^^^^^^^^^^^^^^^^^
  File "/home/alain/anaconda3/lib/python3.12/site-packages/django/core/handlers/base.py", line 220, in _get_response
    response = response.render()
               ^^^^^^^^^^^^^^^^^
  File "/home/alain/anaconda3/lib/python3.12/site-packages/django/template/response.py", line 114, in render
    self.content = self.rendered_content
                   ^^^^^^^^^^^^^^^^^^^^^
  File "/home/alain/anaconda3/lib/python3.12/site-packages/rest_framework/response.py", line 74, in rendered_content
    ret = renderer.render(self.data, accepted_media_type, context)
          ^^^^^^^^^^^^^^^^^^^^^^^^^^^^^^^^^^^^^^^^^^^^^^^^^^^^^^^^
  File "/home/alain/anaconda3/lib/python3.12/site-packages/rest_framework/renderers.py", line 167, in render
    return template.render(context, request=request)
           ^^^^^^^^^^^^^^^^^^^^^^^^^^^^^^^^^^^^^^^^^
  File "/home/alain/anaconda3/lib/python3.12/site-packages/django/template/backends/django.py", line 107, in render
    return self.template.render(context)
           ^^^^^^^^^^^^^^^^^^^^^^^^^^^^^
  File "/home/alain/anaconda3/lib/python3.12/site-packages/django/template/base.py", line 171, in render
    return self._render(context)
           ^^^^^^^^^^^^^^^^^^^^^
  File "/home/alain/anaconda3/lib/python3.12/site-packages/django/template/base.py", line 163, in _render
    return self.nodelist.render(context)
           ^^^^^^^^^^^^^^^^^^^^^^^^^^^^^
  File "/home/alain/anaconda3/lib/python3.12/site-packages/django/template/base.py", line 1008, in render
    return SafeString("".join([node.render_annotated(context) for node in self]))
                               ^^^^^^^^^^^^^^^^^^^^^^^^^^^^^^
  File "/home/alain/anaconda3/lib/python3.12/site-packages/django/template/base.py", line 969, in render_annotated
    return self.render(context)
           ^^^^^^^^^^^^^^^^^^^^
  File "/home/alain/anaconda3/lib/python3.12/site-packages/django/template/defaulttags.py", line 320, in render
    match = condition.eval(context)
            ^^^^^^^^^^^^^^^^^^^^^^^
  File "/home/alain/anaconda3/lib/python3.12/site-packages/django/template/defaulttags.py", line 886, in eval
    return self.value.resolve(context, ignore_failures=True)
           ^^^^^^^^^^^^^^^^^^^^^^^^^^^^^^^^^^^^^^^^^^^^^^^^^
  File "/home/alain/anaconda3/lib/python3.12/site-packages/django/template/base.py", line 718, in resolve
    obj = self.var.resolve(context)
          ^^^^^^^^^^^^^^^^^^^^^^^^^
  File "/home/alain/anaconda3/lib/python3.12/site-packages/django/template/base.py", line 850, in resolve
    value = self._resolve_lookup(context)
            ^^^^^^^^^^^^^^^^^^^^^^^^^^^^^
  File "/home/alain/anaconda3/lib/python3.12/site-packages/django/template/base.py", line 893, in _resolve_lookup
    current = getattr(current, bit)
              ^^^^^^^^^^^^^^^^^^^^^
  File "/home/alain/anaconda3/lib/python3.12/site-packages/rest_framework/serializers.py", line 576, in errors
    ret = super().errors
          ^^^^^^^^^^^^^^
  File "/home/alain/anaconda3/lib/python3.12/site-packages/rest_framework/serializers.py", line 260, in errors
    raise AssertionError(msg)
AssertionError: You must call `.is_valid()` before accessing `.errors`.
ERROR 2025-03-11 01:31:42,122 basehttp "GET /auth/signup/ HTTP/1.1" 500 165748
ERROR 2025-03-11 01:34:55,709 log Internal Server Error: /auth/signup/
Traceback (most recent call last):
  File "/home/alain/anaconda3/lib/python3.12/site-packages/django/db/backends/utils.py", line 105, in _execute
    return self.cursor.execute(sql, params)
           ^^^^^^^^^^^^^^^^^^^^^^^^^^^^^^^^
psycopg2.errors.UndefinedTable: relation "auth_user" does not exist
LINE 1: SELECT 1 AS "a" FROM "auth_user" WHERE "auth_user"."username...
                             ^


The above exception was the direct cause of the following exception:

Traceback (most recent call last):
  File "/home/alain/anaconda3/lib/python3.12/site-packages/django/core/handlers/exception.py", line 55, in inner
    response = get_response(request)
               ^^^^^^^^^^^^^^^^^^^^^
  File "/home/alain/anaconda3/lib/python3.12/site-packages/django/core/handlers/base.py", line 197, in _get_response
    response = wrapped_callback(request, *callback_args, **callback_kwargs)
               ^^^^^^^^^^^^^^^^^^^^^^^^^^^^^^^^^^^^^^^^^^^^^^^^^^^^^^^^^^^^
  File "/home/alain/anaconda3/lib/python3.12/site-packages/django/views/decorators/csrf.py", line 65, in _view_wrapper
    return view_func(request, *args, **kwargs)
           ^^^^^^^^^^^^^^^^^^^^^^^^^^^^^^^^^^^
  File "/home/alain/anaconda3/lib/python3.12/site-packages/django/views/generic/base.py", line 104, in view
    return self.dispatch(request, *args, **kwargs)
           ^^^^^^^^^^^^^^^^^^^^^^^^^^^^^^^^^^^^^^^
  File "/home/alain/anaconda3/lib/python3.12/site-packages/rest_framework/views.py", line 509, in dispatch
    response = self.handle_exception(exc)
               ^^^^^^^^^^^^^^^^^^^^^^^^^^
  File "/home/alain/anaconda3/lib/python3.12/site-packages/rest_framework/views.py", line 469, in handle_exception
    self.raise_uncaught_exception(exc)
  File "/home/alain/anaconda3/lib/python3.12/site-packages/rest_framework/views.py", line 480, in raise_uncaught_exception
    raise exc
  File "/home/alain/anaconda3/lib/python3.12/site-packages/rest_framework/views.py", line 506, in dispatch
    response = handler(request, *args, **kwargs)
               ^^^^^^^^^^^^^^^^^^^^^^^^^^^^^^^^^
  File "/home/alain/Alain/mentorledInternship/mentorledProject/vector_interview_app/views.py", line 18, in post
    if serializer.is_valid():
       ^^^^^^^^^^^^^^^^^^^^^
  File "/home/alain/anaconda3/lib/python3.12/site-packages/rest_framework/serializers.py", line 223, in is_valid
    self._validated_data = self.run_validation(self.initial_data)
                           ^^^^^^^^^^^^^^^^^^^^^^^^^^^^^^^^^^^^^^
  File "/home/alain/anaconda3/lib/python3.12/site-packages/rest_framework/serializers.py", line 442, in run_validation
    value = self.to_internal_value(data)
            ^^^^^^^^^^^^^^^^^^^^^^^^^^^^
  File "/home/alain/anaconda3/lib/python3.12/site-packages/rest_framework/serializers.py", line 499, in to_internal_value
    validated_value = field.run_validation(primitive_value)
                      ^^^^^^^^^^^^^^^^^^^^^^^^^^^^^^^^^^^^^
  File "/home/alain/anaconda3/lib/python3.12/site-packages/rest_framework/fields.py", line 757, in run_validation
    return super().run_validation(data)
           ^^^^^^^^^^^^^^^^^^^^^^^^^^^^
  File "/home/alain/anaconda3/lib/python3.12/site-packages/rest_framework/fields.py", line 539, in run_validation
    self.run_validators(value)
  File "/home/alain/anaconda3/lib/python3.12/site-packages/rest_framework/fields.py", line 551, in run_validators
    validator(value, self)
  File "/home/alain/anaconda3/lib/python3.12/site-packages/rest_framework/validators.py", line 73, in __call__
    if qs_exists(queryset):
       ^^^^^^^^^^^^^^^^^^^
  File "/home/alain/anaconda3/lib/python3.12/site-packages/rest_framework/validators.py", line 21, in qs_exists
    return queryset.exists()
           ^^^^^^^^^^^^^^^^^
  File "/home/alain/anaconda3/lib/python3.12/site-packages/django/db/models/query.py", line 1288, in exists
    return self.query.has_results(using=self.db)
           ^^^^^^^^^^^^^^^^^^^^^^^^^^^^^^^^^^^^^
  File "/home/alain/anaconda3/lib/python3.12/site-packages/django/db/models/sql/query.py", line 660, in has_results
    return compiler.has_results()
           ^^^^^^^^^^^^^^^^^^^^^^
  File "/home/alain/anaconda3/lib/python3.12/site-packages/django/db/models/sql/compiler.py", line 1542, in has_results
    return bool(self.execute_sql(SINGLE))
                ^^^^^^^^^^^^^^^^^^^^^^^^
  File "/home/alain/anaconda3/lib/python3.12/site-packages/django/db/models/sql/compiler.py", line 1574, in execute_sql
    cursor.execute(sql, params)
  File "/home/alain/anaconda3/lib/python3.12/site-packages/django/db/backends/utils.py", line 122, in execute
    return super().execute(sql, params)
           ^^^^^^^^^^^^^^^^^^^^^^^^^^^^
  File "/home/alain/anaconda3/lib/python3.12/site-packages/django/db/backends/utils.py", line 79, in execute
    return self._execute_with_wrappers(
           ^^^^^^^^^^^^^^^^^^^^^^^^^^^^
  File "/home/alain/anaconda3/lib/python3.12/site-packages/django/db/backends/utils.py", line 92, in _execute_with_wrappers
    return executor(sql, params, many, context)
           ^^^^^^^^^^^^^^^^^^^^^^^^^^^^^^^^^^^^
  File "/home/alain/anaconda3/lib/python3.12/site-packages/django/db/backends/utils.py", line 100, in _execute
    with self.db.wrap_database_errors:
         ^^^^^^^^^^^^^^^^^^^^^^^^^^^^
  File "/home/alain/anaconda3/lib/python3.12/site-packages/django/db/utils.py", line 91, in __exit__
    raise dj_exc_value.with_traceback(traceback) from exc_value
  File "/home/alain/anaconda3/lib/python3.12/site-packages/django/db/backends/utils.py", line 105, in _execute
    return self.cursor.execute(sql, params)
           ^^^^^^^^^^^^^^^^^^^^^^^^^^^^^^^^
django.db.utils.ProgrammingError: relation "auth_user" does not exist
LINE 1: SELECT 1 AS "a" FROM "auth_user" WHERE "auth_user"."username...
                             ^

ERROR 2025-03-11 01:34:55,711 basehttp "POST /auth/signup/ HTTP/1.1" 500 196994
ERROR 2025-03-11 01:36:11,578 log Internal Server Error: /auth/signup/
Traceback (most recent call last):
  File "/home/alain/anaconda3/lib/python3.12/site-packages/django/db/backends/utils.py", line 105, in _execute
    return self.cursor.execute(sql, params)
           ^^^^^^^^^^^^^^^^^^^^^^^^^^^^^^^^
psycopg2.errors.UndefinedTable: relation "auth_user" does not exist
LINE 1: SELECT 1 AS "a" FROM "auth_user" WHERE "auth_user"."username...
                             ^


The above exception was the direct cause of the following exception:

Traceback (most recent call last):
  File "/home/alain/anaconda3/lib/python3.12/site-packages/django/core/handlers/exception.py", line 55, in inner
    response = get_response(request)
               ^^^^^^^^^^^^^^^^^^^^^
  File "/home/alain/anaconda3/lib/python3.12/site-packages/django/core/handlers/base.py", line 197, in _get_response
    response = wrapped_callback(request, *callback_args, **callback_kwargs)
               ^^^^^^^^^^^^^^^^^^^^^^^^^^^^^^^^^^^^^^^^^^^^^^^^^^^^^^^^^^^^
  File "/home/alain/anaconda3/lib/python3.12/site-packages/django/views/decorators/csrf.py", line 65, in _view_wrapper
    return view_func(request, *args, **kwargs)
           ^^^^^^^^^^^^^^^^^^^^^^^^^^^^^^^^^^^
  File "/home/alain/anaconda3/lib/python3.12/site-packages/django/views/generic/base.py", line 104, in view
    return self.dispatch(request, *args, **kwargs)
           ^^^^^^^^^^^^^^^^^^^^^^^^^^^^^^^^^^^^^^^
  File "/home/alain/anaconda3/lib/python3.12/site-packages/rest_framework/views.py", line 509, in dispatch
    response = self.handle_exception(exc)
               ^^^^^^^^^^^^^^^^^^^^^^^^^^
  File "/home/alain/anaconda3/lib/python3.12/site-packages/rest_framework/views.py", line 469, in handle_exception
    self.raise_uncaught_exception(exc)
  File "/home/alain/anaconda3/lib/python3.12/site-packages/rest_framework/views.py", line 480, in raise_uncaught_exception
    raise exc
  File "/home/alain/anaconda3/lib/python3.12/site-packages/rest_framework/views.py", line 506, in dispatch
    response = handler(request, *args, **kwargs)
               ^^^^^^^^^^^^^^^^^^^^^^^^^^^^^^^^^
  File "/home/alain/Alain/mentorledInternship/mentorledProject/vector_interview_app/views.py", line 18, in post
    if serializer.is_valid():
       ^^^^^^^^^^^^^^^^^^^^^
  File "/home/alain/anaconda3/lib/python3.12/site-packages/rest_framework/serializers.py", line 223, in is_valid
    self._validated_data = self.run_validation(self.initial_data)
                           ^^^^^^^^^^^^^^^^^^^^^^^^^^^^^^^^^^^^^^
  File "/home/alain/anaconda3/lib/python3.12/site-packages/rest_framework/serializers.py", line 442, in run_validation
    value = self.to_internal_value(data)
            ^^^^^^^^^^^^^^^^^^^^^^^^^^^^
  File "/home/alain/anaconda3/lib/python3.12/site-packages/rest_framework/serializers.py", line 499, in to_internal_value
    validated_value = field.run_validation(primitive_value)
                      ^^^^^^^^^^^^^^^^^^^^^^^^^^^^^^^^^^^^^
  File "/home/alain/anaconda3/lib/python3.12/site-packages/rest_framework/fields.py", line 757, in run_validation
    return super().run_validation(data)
           ^^^^^^^^^^^^^^^^^^^^^^^^^^^^
  File "/home/alain/anaconda3/lib/python3.12/site-packages/rest_framework/fields.py", line 539, in run_validation
    self.run_validators(value)
  File "/home/alain/anaconda3/lib/python3.12/site-packages/rest_framework/fields.py", line 551, in run_validators
    validator(value, self)
  File "/home/alain/anaconda3/lib/python3.12/site-packages/rest_framework/validators.py", line 73, in __call__
    if qs_exists(queryset):
       ^^^^^^^^^^^^^^^^^^^
  File "/home/alain/anaconda3/lib/python3.12/site-packages/rest_framework/validators.py", line 21, in qs_exists
    return queryset.exists()
           ^^^^^^^^^^^^^^^^^
  File "/home/alain/anaconda3/lib/python3.12/site-packages/django/db/models/query.py", line 1288, in exists
    return self.query.has_results(using=self.db)
           ^^^^^^^^^^^^^^^^^^^^^^^^^^^^^^^^^^^^^
  File "/home/alain/anaconda3/lib/python3.12/site-packages/django/db/models/sql/query.py", line 660, in has_results
    return compiler.has_results()
           ^^^^^^^^^^^^^^^^^^^^^^
  File "/home/alain/anaconda3/lib/python3.12/site-packages/django/db/models/sql/compiler.py", line 1542, in has_results
    return bool(self.execute_sql(SINGLE))
                ^^^^^^^^^^^^^^^^^^^^^^^^
  File "/home/alain/anaconda3/lib/python3.12/site-packages/django/db/models/sql/compiler.py", line 1574, in execute_sql
    cursor.execute(sql, params)
  File "/home/alain/anaconda3/lib/python3.12/site-packages/django/db/backends/utils.py", line 122, in execute
    return super().execute(sql, params)
           ^^^^^^^^^^^^^^^^^^^^^^^^^^^^
  File "/home/alain/anaconda3/lib/python3.12/site-packages/django/db/backends/utils.py", line 79, in execute
    return self._execute_with_wrappers(
           ^^^^^^^^^^^^^^^^^^^^^^^^^^^^
  File "/home/alain/anaconda3/lib/python3.12/site-packages/django/db/backends/utils.py", line 92, in _execute_with_wrappers
    return executor(sql, params, many, context)
           ^^^^^^^^^^^^^^^^^^^^^^^^^^^^^^^^^^^^
  File "/home/alain/anaconda3/lib/python3.12/site-packages/django/db/backends/utils.py", line 100, in _execute
    with self.db.wrap_database_errors:
         ^^^^^^^^^^^^^^^^^^^^^^^^^^^^
  File "/home/alain/anaconda3/lib/python3.12/site-packages/django/db/utils.py", line 91, in __exit__
    raise dj_exc_value.with_traceback(traceback) from exc_value
  File "/home/alain/anaconda3/lib/python3.12/site-packages/django/db/backends/utils.py", line 105, in _execute
    return self.cursor.execute(sql, params)
           ^^^^^^^^^^^^^^^^^^^^^^^^^^^^^^^^
django.db.utils.ProgrammingError: relation "auth_user" does not exist
LINE 1: SELECT 1 AS "a" FROM "auth_user" WHERE "auth_user"."username...
                             ^

ERROR 2025-03-11 01:36:11,580 basehttp "POST /auth/signup/ HTTP/1.1" 500 196994
ERROR 2025-03-11 01:36:23,889 log Internal Server Error: /auth/signup/
Traceback (most recent call last):
  File "/home/alain/anaconda3/lib/python3.12/site-packages/django/db/backends/utils.py", line 105, in _execute
    return self.cursor.execute(sql, params)
           ^^^^^^^^^^^^^^^^^^^^^^^^^^^^^^^^
psycopg2.errors.UndefinedTable: relation "auth_user" does not exist
LINE 1: SELECT 1 AS "a" FROM "auth_user" WHERE "auth_user"."username...
                             ^


The above exception was the direct cause of the following exception:

Traceback (most recent call last):
  File "/home/alain/anaconda3/lib/python3.12/site-packages/django/core/handlers/exception.py", line 55, in inner
    response = get_response(request)
               ^^^^^^^^^^^^^^^^^^^^^
  File "/home/alain/anaconda3/lib/python3.12/site-packages/django/core/handlers/base.py", line 197, in _get_response
    response = wrapped_callback(request, *callback_args, **callback_kwargs)
               ^^^^^^^^^^^^^^^^^^^^^^^^^^^^^^^^^^^^^^^^^^^^^^^^^^^^^^^^^^^^
  File "/home/alain/anaconda3/lib/python3.12/site-packages/django/views/decorators/csrf.py", line 65, in _view_wrapper
    return view_func(request, *args, **kwargs)
           ^^^^^^^^^^^^^^^^^^^^^^^^^^^^^^^^^^^
  File "/home/alain/anaconda3/lib/python3.12/site-packages/django/views/generic/base.py", line 104, in view
    return self.dispatch(request, *args, **kwargs)
           ^^^^^^^^^^^^^^^^^^^^^^^^^^^^^^^^^^^^^^^
  File "/home/alain/anaconda3/lib/python3.12/site-packages/rest_framework/views.py", line 509, in dispatch
    response = self.handle_exception(exc)
               ^^^^^^^^^^^^^^^^^^^^^^^^^^
  File "/home/alain/anaconda3/lib/python3.12/site-packages/rest_framework/views.py", line 469, in handle_exception
    self.raise_uncaught_exception(exc)
  File "/home/alain/anaconda3/lib/python3.12/site-packages/rest_framework/views.py", line 480, in raise_uncaught_exception
    raise exc
  File "/home/alain/anaconda3/lib/python3.12/site-packages/rest_framework/views.py", line 506, in dispatch
    response = handler(request, *args, **kwargs)
               ^^^^^^^^^^^^^^^^^^^^^^^^^^^^^^^^^
  File "/home/alain/Alain/mentorledInternship/mentorledProject/vector_interview_app/views.py", line 18, in post
    if serializer.is_valid():
       ^^^^^^^^^^^^^^^^^^^^^
  File "/home/alain/anaconda3/lib/python3.12/site-packages/rest_framework/serializers.py", line 223, in is_valid
    self._validated_data = self.run_validation(self.initial_data)
                           ^^^^^^^^^^^^^^^^^^^^^^^^^^^^^^^^^^^^^^
  File "/home/alain/anaconda3/lib/python3.12/site-packages/rest_framework/serializers.py", line 442, in run_validation
    value = self.to_internal_value(data)
            ^^^^^^^^^^^^^^^^^^^^^^^^^^^^
  File "/home/alain/anaconda3/lib/python3.12/site-packages/rest_framework/serializers.py", line 499, in to_internal_value
    validated_value = field.run_validation(primitive_value)
                      ^^^^^^^^^^^^^^^^^^^^^^^^^^^^^^^^^^^^^
  File "/home/alain/anaconda3/lib/python3.12/site-packages/rest_framework/fields.py", line 757, in run_validation
    return super().run_validation(data)
           ^^^^^^^^^^^^^^^^^^^^^^^^^^^^
  File "/home/alain/anaconda3/lib/python3.12/site-packages/rest_framework/fields.py", line 539, in run_validation
    self.run_validators(value)
  File "/home/alain/anaconda3/lib/python3.12/site-packages/rest_framework/fields.py", line 551, in run_validators
    validator(value, self)
  File "/home/alain/anaconda3/lib/python3.12/site-packages/rest_framework/validators.py", line 73, in __call__
    if qs_exists(queryset):
       ^^^^^^^^^^^^^^^^^^^
  File "/home/alain/anaconda3/lib/python3.12/site-packages/rest_framework/validators.py", line 21, in qs_exists
    return queryset.exists()
           ^^^^^^^^^^^^^^^^^
  File "/home/alain/anaconda3/lib/python3.12/site-packages/django/db/models/query.py", line 1288, in exists
    return self.query.has_results(using=self.db)
           ^^^^^^^^^^^^^^^^^^^^^^^^^^^^^^^^^^^^^
  File "/home/alain/anaconda3/lib/python3.12/site-packages/django/db/models/sql/query.py", line 660, in has_results
    return compiler.has_results()
           ^^^^^^^^^^^^^^^^^^^^^^
  File "/home/alain/anaconda3/lib/python3.12/site-packages/django/db/models/sql/compiler.py", line 1542, in has_results
    return bool(self.execute_sql(SINGLE))
                ^^^^^^^^^^^^^^^^^^^^^^^^
  File "/home/alain/anaconda3/lib/python3.12/site-packages/django/db/models/sql/compiler.py", line 1574, in execute_sql
    cursor.execute(sql, params)
  File "/home/alain/anaconda3/lib/python3.12/site-packages/django/db/backends/utils.py", line 122, in execute
    return super().execute(sql, params)
           ^^^^^^^^^^^^^^^^^^^^^^^^^^^^
  File "/home/alain/anaconda3/lib/python3.12/site-packages/django/db/backends/utils.py", line 79, in execute
    return self._execute_with_wrappers(
           ^^^^^^^^^^^^^^^^^^^^^^^^^^^^
  File "/home/alain/anaconda3/lib/python3.12/site-packages/django/db/backends/utils.py", line 92, in _execute_with_wrappers
    return executor(sql, params, many, context)
           ^^^^^^^^^^^^^^^^^^^^^^^^^^^^^^^^^^^^
  File "/home/alain/anaconda3/lib/python3.12/site-packages/django/db/backends/utils.py", line 100, in _execute
    with self.db.wrap_database_errors:
         ^^^^^^^^^^^^^^^^^^^^^^^^^^^^
  File "/home/alain/anaconda3/lib/python3.12/site-packages/django/db/utils.py", line 91, in __exit__
    raise dj_exc_value.with_traceback(traceback) from exc_value
  File "/home/alain/anaconda3/lib/python3.12/site-packages/django/db/backends/utils.py", line 105, in _execute
    return self.cursor.execute(sql, params)
           ^^^^^^^^^^^^^^^^^^^^^^^^^^^^^^^^
django.db.utils.ProgrammingError: relation "auth_user" does not exist
LINE 1: SELECT 1 AS "a" FROM "auth_user" WHERE "auth_user"."username...
                             ^

ERROR 2025-03-11 01:36:23,891 basehttp "POST /auth/signup/ HTTP/1.1" 500 196994
ERROR 2025-03-11 01:44:58,819 log Internal Server Error: /auth/signup/
Traceback (most recent call last):
  File "/home/alain/anaconda3/lib/python3.12/site-packages/django/db/backends/utils.py", line 105, in _execute
    return self.cursor.execute(sql, params)
           ^^^^^^^^^^^^^^^^^^^^^^^^^^^^^^^^
psycopg2.errors.UndefinedTable: relation "vector_interview_app_vectoruser" does not exist
LINE 1: SELECT 1 AS "a" FROM "vector_interview_app_vectoruser" WHERE...
                             ^


The above exception was the direct cause of the following exception:

Traceback (most recent call last):
  File "/home/alain/anaconda3/lib/python3.12/site-packages/django/core/handlers/exception.py", line 55, in inner
    response = get_response(request)
               ^^^^^^^^^^^^^^^^^^^^^
  File "/home/alain/anaconda3/lib/python3.12/site-packages/django/core/handlers/base.py", line 197, in _get_response
    response = wrapped_callback(request, *callback_args, **callback_kwargs)
               ^^^^^^^^^^^^^^^^^^^^^^^^^^^^^^^^^^^^^^^^^^^^^^^^^^^^^^^^^^^^
  File "/home/alain/anaconda3/lib/python3.12/site-packages/django/views/decorators/csrf.py", line 65, in _view_wrapper
    return view_func(request, *args, **kwargs)
           ^^^^^^^^^^^^^^^^^^^^^^^^^^^^^^^^^^^
  File "/home/alain/anaconda3/lib/python3.12/site-packages/django/views/generic/base.py", line 104, in view
    return self.dispatch(request, *args, **kwargs)
           ^^^^^^^^^^^^^^^^^^^^^^^^^^^^^^^^^^^^^^^
  File "/home/alain/anaconda3/lib/python3.12/site-packages/rest_framework/views.py", line 509, in dispatch
    response = self.handle_exception(exc)
               ^^^^^^^^^^^^^^^^^^^^^^^^^^
  File "/home/alain/anaconda3/lib/python3.12/site-packages/rest_framework/views.py", line 469, in handle_exception
    self.raise_uncaught_exception(exc)
  File "/home/alain/anaconda3/lib/python3.12/site-packages/rest_framework/views.py", line 480, in raise_uncaught_exception
    raise exc
  File "/home/alain/anaconda3/lib/python3.12/site-packages/rest_framework/views.py", line 506, in dispatch
    response = handler(request, *args, **kwargs)
               ^^^^^^^^^^^^^^^^^^^^^^^^^^^^^^^^^
  File "/home/alain/Alain/mentorledInternship/mentorledProject/vector_interview_app/views.py", line 18, in post
    if serializer.is_valid():
       ^^^^^^^^^^^^^^^^^^^^^
  File "/home/alain/anaconda3/lib/python3.12/site-packages/rest_framework/serializers.py", line 223, in is_valid
    self._validated_data = self.run_validation(self.initial_data)
                           ^^^^^^^^^^^^^^^^^^^^^^^^^^^^^^^^^^^^^^
  File "/home/alain/anaconda3/lib/python3.12/site-packages/rest_framework/serializers.py", line 442, in run_validation
    value = self.to_internal_value(data)
            ^^^^^^^^^^^^^^^^^^^^^^^^^^^^
  File "/home/alain/anaconda3/lib/python3.12/site-packages/rest_framework/serializers.py", line 499, in to_internal_value
    validated_value = field.run_validation(primitive_value)
                      ^^^^^^^^^^^^^^^^^^^^^^^^^^^^^^^^^^^^^
  File "/home/alain/anaconda3/lib/python3.12/site-packages/rest_framework/fields.py", line 757, in run_validation
    return super().run_validation(data)
           ^^^^^^^^^^^^^^^^^^^^^^^^^^^^
  File "/home/alain/anaconda3/lib/python3.12/site-packages/rest_framework/fields.py", line 539, in run_validation
    self.run_validators(value)
  File "/home/alain/anaconda3/lib/python3.12/site-packages/rest_framework/fields.py", line 551, in run_validators
    validator(value, self)
  File "/home/alain/anaconda3/lib/python3.12/site-packages/rest_framework/validators.py", line 73, in __call__
    if qs_exists(queryset):
       ^^^^^^^^^^^^^^^^^^^
  File "/home/alain/anaconda3/lib/python3.12/site-packages/rest_framework/validators.py", line 21, in qs_exists
    return queryset.exists()
           ^^^^^^^^^^^^^^^^^
  File "/home/alain/anaconda3/lib/python3.12/site-packages/django/db/models/query.py", line 1288, in exists
    return self.query.has_results(using=self.db)
           ^^^^^^^^^^^^^^^^^^^^^^^^^^^^^^^^^^^^^
  File "/home/alain/anaconda3/lib/python3.12/site-packages/django/db/models/sql/query.py", line 660, in has_results
    return compiler.has_results()
           ^^^^^^^^^^^^^^^^^^^^^^
  File "/home/alain/anaconda3/lib/python3.12/site-packages/django/db/models/sql/compiler.py", line 1542, in has_results
    return bool(self.execute_sql(SINGLE))
                ^^^^^^^^^^^^^^^^^^^^^^^^
  File "/home/alain/anaconda3/lib/python3.12/site-packages/django/db/models/sql/compiler.py", line 1574, in execute_sql
    cursor.execute(sql, params)
  File "/home/alain/anaconda3/lib/python3.12/site-packages/django/db/backends/utils.py", line 122, in execute
    return super().execute(sql, params)
           ^^^^^^^^^^^^^^^^^^^^^^^^^^^^
  File "/home/alain/anaconda3/lib/python3.12/site-packages/django/db/backends/utils.py", line 79, in execute
    return self._execute_with_wrappers(
           ^^^^^^^^^^^^^^^^^^^^^^^^^^^^
  File "/home/alain/anaconda3/lib/python3.12/site-packages/django/db/backends/utils.py", line 92, in _execute_with_wrappers
    return executor(sql, params, many, context)
           ^^^^^^^^^^^^^^^^^^^^^^^^^^^^^^^^^^^^
  File "/home/alain/anaconda3/lib/python3.12/site-packages/django/db/backends/utils.py", line 100, in _execute
    with self.db.wrap_database_errors:
         ^^^^^^^^^^^^^^^^^^^^^^^^^^^^
  File "/home/alain/anaconda3/lib/python3.12/site-packages/django/db/utils.py", line 91, in __exit__
    raise dj_exc_value.with_traceback(traceback) from exc_value
  File "/home/alain/anaconda3/lib/python3.12/site-packages/django/db/backends/utils.py", line 105, in _execute
    return self.cursor.execute(sql, params)
           ^^^^^^^^^^^^^^^^^^^^^^^^^^^^^^^^
django.db.utils.ProgrammingError: relation "vector_interview_app_vectoruser" does not exist
LINE 1: SELECT 1 AS "a" FROM "vector_interview_app_vectoruser" WHERE...
                             ^

ERROR 2025-03-11 01:44:58,822 basehttp "POST /auth/signup/ HTTP/1.1" 500 197632
ERROR 2025-03-11 01:56:35,784 log Internal Server Error: /auth/signup/
Traceback (most recent call last):
  File "/home/alain/anaconda3/lib/python3.12/site-packages/django/db/backends/utils.py", line 105, in _execute
    return self.cursor.execute(sql, params)
           ^^^^^^^^^^^^^^^^^^^^^^^^^^^^^^^^
psycopg2.errors.UndefinedTable: relation "vector_interview_app_vectoruser" does not exist
LINE 1: SELECT 1 AS "a" FROM "vector_interview_app_vectoruser" WHERE...
                             ^


The above exception was the direct cause of the following exception:

Traceback (most recent call last):
  File "/home/alain/anaconda3/lib/python3.12/site-packages/django/core/handlers/exception.py", line 55, in inner
    response = get_response(request)
               ^^^^^^^^^^^^^^^^^^^^^
  File "/home/alain/anaconda3/lib/python3.12/site-packages/django/core/handlers/base.py", line 197, in _get_response
    response = wrapped_callback(request, *callback_args, **callback_kwargs)
               ^^^^^^^^^^^^^^^^^^^^^^^^^^^^^^^^^^^^^^^^^^^^^^^^^^^^^^^^^^^^
  File "/home/alain/anaconda3/lib/python3.12/site-packages/django/views/decorators/csrf.py", line 65, in _view_wrapper
    return view_func(request, *args, **kwargs)
           ^^^^^^^^^^^^^^^^^^^^^^^^^^^^^^^^^^^
  File "/home/alain/anaconda3/lib/python3.12/site-packages/django/views/generic/base.py", line 104, in view
    return self.dispatch(request, *args, **kwargs)
           ^^^^^^^^^^^^^^^^^^^^^^^^^^^^^^^^^^^^^^^
  File "/home/alain/anaconda3/lib/python3.12/site-packages/rest_framework/views.py", line 509, in dispatch
    response = self.handle_exception(exc)
               ^^^^^^^^^^^^^^^^^^^^^^^^^^
  File "/home/alain/anaconda3/lib/python3.12/site-packages/rest_framework/views.py", line 469, in handle_exception
    self.raise_uncaught_exception(exc)
  File "/home/alain/anaconda3/lib/python3.12/site-packages/rest_framework/views.py", line 480, in raise_uncaught_exception
    raise exc
  File "/home/alain/anaconda3/lib/python3.12/site-packages/rest_framework/views.py", line 506, in dispatch
    response = handler(request, *args, **kwargs)
               ^^^^^^^^^^^^^^^^^^^^^^^^^^^^^^^^^
  File "/home/alain/Alain/mentorledInternship/mentorledProject/vector_interview_app/views.py", line 18, in post
    if serializer.is_valid():
       ^^^^^^^^^^^^^^^^^^^^^
  File "/home/alain/anaconda3/lib/python3.12/site-packages/rest_framework/serializers.py", line 223, in is_valid
    self._validated_data = self.run_validation(self.initial_data)
                           ^^^^^^^^^^^^^^^^^^^^^^^^^^^^^^^^^^^^^^
  File "/home/alain/anaconda3/lib/python3.12/site-packages/rest_framework/serializers.py", line 442, in run_validation
    value = self.to_internal_value(data)
            ^^^^^^^^^^^^^^^^^^^^^^^^^^^^
  File "/home/alain/anaconda3/lib/python3.12/site-packages/rest_framework/serializers.py", line 499, in to_internal_value
    validated_value = field.run_validation(primitive_value)
                      ^^^^^^^^^^^^^^^^^^^^^^^^^^^^^^^^^^^^^
  File "/home/alain/anaconda3/lib/python3.12/site-packages/rest_framework/fields.py", line 757, in run_validation
    return super().run_validation(data)
           ^^^^^^^^^^^^^^^^^^^^^^^^^^^^
  File "/home/alain/anaconda3/lib/python3.12/site-packages/rest_framework/fields.py", line 539, in run_validation
    self.run_validators(value)
  File "/home/alain/anaconda3/lib/python3.12/site-packages/rest_framework/fields.py", line 551, in run_validators
    validator(value, self)
  File "/home/alain/anaconda3/lib/python3.12/site-packages/rest_framework/validators.py", line 73, in __call__
    if qs_exists(queryset):
       ^^^^^^^^^^^^^^^^^^^
  File "/home/alain/anaconda3/lib/python3.12/site-packages/rest_framework/validators.py", line 21, in qs_exists
    return queryset.exists()
           ^^^^^^^^^^^^^^^^^
  File "/home/alain/anaconda3/lib/python3.12/site-packages/django/db/models/query.py", line 1288, in exists
    return self.query.has_results(using=self.db)
           ^^^^^^^^^^^^^^^^^^^^^^^^^^^^^^^^^^^^^
  File "/home/alain/anaconda3/lib/python3.12/site-packages/django/db/models/sql/query.py", line 660, in has_results
    return compiler.has_results()
           ^^^^^^^^^^^^^^^^^^^^^^
  File "/home/alain/anaconda3/lib/python3.12/site-packages/django/db/models/sql/compiler.py", line 1542, in has_results
    return bool(self.execute_sql(SINGLE))
                ^^^^^^^^^^^^^^^^^^^^^^^^
  File "/home/alain/anaconda3/lib/python3.12/site-packages/django/db/models/sql/compiler.py", line 1574, in execute_sql
    cursor.execute(sql, params)
  File "/home/alain/anaconda3/lib/python3.12/site-packages/django/db/backends/utils.py", line 122, in execute
    return super().execute(sql, params)
           ^^^^^^^^^^^^^^^^^^^^^^^^^^^^
  File "/home/alain/anaconda3/lib/python3.12/site-packages/django/db/backends/utils.py", line 79, in execute
    return self._execute_with_wrappers(
           ^^^^^^^^^^^^^^^^^^^^^^^^^^^^
  File "/home/alain/anaconda3/lib/python3.12/site-packages/django/db/backends/utils.py", line 92, in _execute_with_wrappers
    return executor(sql, params, many, context)
           ^^^^^^^^^^^^^^^^^^^^^^^^^^^^^^^^^^^^
  File "/home/alain/anaconda3/lib/python3.12/site-packages/django/db/backends/utils.py", line 100, in _execute
    with self.db.wrap_database_errors:
         ^^^^^^^^^^^^^^^^^^^^^^^^^^^^
  File "/home/alain/anaconda3/lib/python3.12/site-packages/django/db/utils.py", line 91, in __exit__
    raise dj_exc_value.with_traceback(traceback) from exc_value
  File "/home/alain/anaconda3/lib/python3.12/site-packages/django/db/backends/utils.py", line 105, in _execute
    return self.cursor.execute(sql, params)
           ^^^^^^^^^^^^^^^^^^^^^^^^^^^^^^^^
django.db.utils.ProgrammingError: relation "vector_interview_app_vectoruser" does not exist
LINE 1: SELECT 1 AS "a" FROM "vector_interview_app_vectoruser" WHERE...
                             ^

ERROR 2025-03-11 01:56:35,787 basehttp "POST /auth/signup/ HTTP/1.1" 500 197632
ERROR 2025-03-11 03:49:16,743 log Internal Server Error: /auth/login/
Traceback (most recent call last):
  File "/home/alain/anaconda3/lib/python3.12/site-packages/django/core/handlers/exception.py", line 55, in inner
    response = get_response(request)
               ^^^^^^^^^^^^^^^^^^^^^
  File "/home/alain/anaconda3/lib/python3.12/site-packages/django/core/handlers/base.py", line 197, in _get_response
    response = wrapped_callback(request, *callback_args, **callback_kwargs)
               ^^^^^^^^^^^^^^^^^^^^^^^^^^^^^^^^^^^^^^^^^^^^^^^^^^^^^^^^^^^^
  File "/home/alain/anaconda3/lib/python3.12/site-packages/django/views/decorators/csrf.py", line 65, in _view_wrapper
    return view_func(request, *args, **kwargs)
           ^^^^^^^^^^^^^^^^^^^^^^^^^^^^^^^^^^^
  File "/home/alain/anaconda3/lib/python3.12/site-packages/django/views/generic/base.py", line 104, in view
    return self.dispatch(request, *args, **kwargs)
           ^^^^^^^^^^^^^^^^^^^^^^^^^^^^^^^^^^^^^^^
  File "/home/alain/anaconda3/lib/python3.12/site-packages/rest_framework/views.py", line 509, in dispatch
    response = self.handle_exception(exc)
               ^^^^^^^^^^^^^^^^^^^^^^^^^^
  File "/home/alain/anaconda3/lib/python3.12/site-packages/rest_framework/views.py", line 469, in handle_exception
    self.raise_uncaught_exception(exc)
  File "/home/alain/anaconda3/lib/python3.12/site-packages/rest_framework/views.py", line 480, in raise_uncaught_exception
    raise exc
  File "/home/alain/anaconda3/lib/python3.12/site-packages/rest_framework/views.py", line 506, in dispatch
    response = handler(request, *args, **kwargs)
               ^^^^^^^^^^^^^^^^^^^^^^^^^^^^^^^^^
  File "/home/alain/Alain/mentorledInternship/mentorledProject/vector_interview_app/views.py", line 54, in post
    return redirect('home')
           ^^^^^^^^^^^^^^^^
  File "/home/alain/anaconda3/lib/python3.12/site-packages/django/shortcuts.py", line 49, in redirect
    return redirect_class(resolve_url(to, *args, **kwargs))
                          ^^^^^^^^^^^^^^^^^^^^^^^^^^^^^^^^
  File "/home/alain/anaconda3/lib/python3.12/site-packages/django/shortcuts.py", line 180, in resolve_url
    return reverse(to, args=args, kwargs=kwargs)
           ^^^^^^^^^^^^^^^^^^^^^^^^^^^^^^^^^^^^^
  File "/home/alain/anaconda3/lib/python3.12/site-packages/django/urls/base.py", line 88, in reverse
    return resolver._reverse_with_prefix(view, prefix, *args, **kwargs)
           ^^^^^^^^^^^^^^^^^^^^^^^^^^^^^^^^^^^^^^^^^^^^^^^^^^^^^^^^^^^^
  File "/home/alain/anaconda3/lib/python3.12/site-packages/django/urls/resolvers.py", line 831, in _reverse_with_prefix
    raise NoReverseMatch(msg)
django.urls.exceptions.NoReverseMatch: Reverse for 'home' not found. 'home' is not a valid view function or pattern name.
ERROR 2025-03-11 03:49:16,745 basehttp "POST /auth/login/ HTTP/1.1" 500 122897
ERROR 2025-03-11 03:53:53,071 log Internal Server Error: /auth/home/
Traceback (most recent call last):
  File "/home/alain/anaconda3/lib/python3.12/site-packages/django/core/handlers/exception.py", line 55, in inner
    response = get_response(request)
               ^^^^^^^^^^^^^^^^^^^^^
  File "/home/alain/anaconda3/lib/python3.12/site-packages/django/core/handlers/base.py", line 197, in _get_response
    response = wrapped_callback(request, *callback_args, **callback_kwargs)
               ^^^^^^^^^^^^^^^^^^^^^^^^^^^^^^^^^^^^^^^^^^^^^^^^^^^^^^^^^^^^
  File "/home/alain/Alain/mentorledInternship/mentorledProject/vector_interview_app/views.py", line 72, in home
    return render(request,'home.html',{})
           ^^^^^^
NameError: name 'render' is not defined
ERROR 2025-03-11 03:53:53,072 basehttp "GET /auth/home/ HTTP/1.1" 500 73461
WARNING 2025-03-11 03:55:06,264 log Not Found: /favicon.ico
